{
  "test_type": "ULTIMATE_COMPREHENSIVE",
  "timestamp": "2025-07-13T23:03:34.614648",
  "summary": {
    "total_tests": 56,
    "passed": 43,
    "failed": 12,
    "warnings": 1,
    "info": 0,
    "skipped": 0,
    "success_rate": 76.78571428571429
  },
  "category_breakdown": {
    "FILE_SYSTEM": {
      "total": 12,
      "passed": 12,
      "success_rate": 100.0
    },
    "PYTHON_ENV": {
      "total": 9,
      "passed": 8,
      "success_rate": 88.88888888888889
    },
    "BACKEND_HEALTH": {
      "total": 1,
      "passed": 0,
      "success_rate": 0.0
    },
    "API_ENDPOINTS": {
      "total": 4,
      "passed": 0,
      "success_rate": 0.0
    },
    "CRYPTO": {
      "total": 2,
      "passed": 2,
      "success_rate": 100.0
    },
    "DATA_VALIDATION": {
      "total": 7,
      "passed": 6,
      "success_rate": 85.71428571428571
    },
    "SECURITY": {
      "total": 3,
      "passed": 3,
      "success_rate": 100.0
    },
    "PERFORMANCE": {
      "total": 2,
      "passed": 0,
      "success_rate": 0.0
    },
    "INSTALLER": {
      "total": 6,
      "passed": 6,
      "success_rate": 100.0
    },
    "DOCUMENTATION": {
      "total": 7,
      "passed": 6,
      "success_rate": 85.71428571428571
    },
    "ERROR_HANDLING": {
      "total": 3,
      "passed": 0,
      "success_rate": 0.0
    }
  },
  "detailed_results": [
    {
      "timestamp": "2025-07-13T23:03:33.861837",
      "category": "FILE_SYSTEM",
      "test": "Main application exists",
      "status": "PASS",
      "details": "Size: 8801 bytes",
      "error": null
    },
    {
      "timestamp": "2025-07-13T23:03:33.864647",
      "category": "FILE_SYSTEM",
      "test": "Secure application exists",
      "status": "PASS",
      "details": "Size: 26306 bytes",
      "error": null
    },
    {
      "timestamp": "2025-07-13T23:03:33.867771",
      "category": "FILE_SYSTEM",
      "test": "Installer builder exists",
      "status": "PASS",
      "details": "Size: 35829 bytes",
      "error": null
    },
    {
      "timestamp": "2025-07-13T23:03:33.870431",
      "category": "FILE_SYSTEM",
      "test": "Dependencies exists",
      "status": "PASS",
      "details": "Size: 1210 bytes",
      "error": null
    },
    {
      "timestamp": "2025-07-13T23:03:33.873314",
      "category": "FILE_SYSTEM",
      "test": "Documentation exists",
      "status": "PASS",
      "details": "Size: 7990 bytes",
      "error": null
    },
    {
      "timestamp": "2025-07-13T23:03:33.876046",
      "category": "FILE_SYSTEM",
      "test": "Setup script exists",
      "status": "PASS",
      "details": "Size: 16231 bytes",
      "error": null
    },
    {
      "timestamp": "2025-07-13T23:03:33.878688",
      "category": "FILE_SYSTEM",
      "test": "backend/main.py readable",
      "status": "PASS",
      "details": "",
      "error": null
    },
    {
      "timestamp": "2025-07-13T23:03:33.880742",
      "category": "FILE_SYSTEM",
      "test": "simple_main_with_security.py readable",
      "status": "PASS",
      "details": "",
      "error": null
    },
    {
      "timestamp": "2025-07-13T23:03:33.882882",
      "category": "FILE_SYSTEM",
      "test": "build_installer.py readable",
      "status": "PASS",
      "details": "",
      "error": null
    },
    {
      "timestamp": "2025-07-13T23:03:33.885487",
      "category": "FILE_SYSTEM",
      "test": "requirements.txt readable",
      "status": "PASS",
      "details": "",
      "error": null
    },
    {
      "timestamp": "2025-07-13T23:03:33.887694",
      "category": "FILE_SYSTEM",
      "test": "README.md readable",
      "status": "PASS",
      "details": "",
      "error": null
    },
    {
      "timestamp": "2025-07-13T23:03:33.890118",
      "category": "FILE_SYSTEM",
      "test": "setup.py readable",
      "status": "PASS",
      "details": "",
      "error": null
    },
    {
      "timestamp": "2025-07-13T23:03:33.890248",
      "category": "PYTHON_ENV",
      "test": "Python version",
      "status": "PASS",
      "details": "Python 3.12.3",
      "error": null
    },
    {
      "timestamp": "2025-07-13T23:03:34.505070",
      "category": "PYTHON_ENV",
      "test": "Import fastapi",
      "status": "PASS",
      "details": "",
      "error": null
    },
    {
      "timestamp": "2025-07-13T23:03:34.551313",
      "category": "PYTHON_ENV",
      "test": "Import uvicorn",
      "status": "PASS",
      "details": "",
      "error": null
    },
    {
      "timestamp": "2025-07-13T23:03:34.551421",
      "category": "PYTHON_ENV",
      "test": "Import pydantic",
      "status": "PASS",
      "details": "",
      "error": null
    },
    {
      "timestamp": "2025-07-13T23:03:34.552230",
      "category": "PYTHON_ENV",
      "test": "Import sqlalchemy",
      "status": "FAIL",
      "details": "",
      "error": "No module named 'sqlalchemy'"
    },
    {
      "timestamp": "2025-07-13T23:03:34.552312",
      "category": "PYTHON_ENV",
      "test": "Import requests",
      "status": "PASS",
      "details": "",
      "error": null
    },
    {
      "timestamp": "2025-07-13T23:03:34.552388",
      "category": "PYTHON_ENV",
      "test": "Import json",
      "status": "PASS",
      "details": "",
      "error": null
    },
    {
      "timestamp": "2025-07-13T23:03:34.552448",
      "category": "PYTHON_ENV",
      "test": "Import hashlib",
      "status": "PASS",
      "details": "",
      "error": null
    },
    {
      "timestamp": "2025-07-13T23:03:34.552506",
      "category": "PYTHON_ENV",
      "test": "Import datetime",
      "status": "PASS",
      "details": "",
      "error": null
    },
    {
      "timestamp": "2025-07-13T23:03:34.557192",
      "category": "BACKEND_HEALTH",
      "test": "Server health check",
      "status": "FAIL",
      "details": "",
      "error": "HTTPConnectionPool(host='localhost', port=8000): Max retries exceeded with url: /health (Caused by NewConnectionError('<urllib3.connection.HTTPConnection object at 0x78b80b5ddfd0>: Failed to establish a new connection: [Errno 111] Connection refused'))"
    },
    {
      "timestamp": "2025-07-13T23:03:34.558412",
      "category": "API_ENDPOINTS",
      "test": "Root endpoint error",
      "status": "FAIL",
      "details": "",
      "error": "HTTPConnectionPool(host='localhost', port=8000): Max retries exceeded with url: / (Caused by NewConnectionError('<urllib3.connection.HTTPConnection object at 0x78b80b49d910>: Failed to establish a new connection: [Errno 111] Connection refused'))"
    },
    {
      "timestamp": "2025-07-13T23:03:34.559339",
      "category": "API_ENDPOINTS",
      "test": "Health endpoint error",
      "status": "FAIL",
      "details": "",
      "error": "HTTPConnectionPool(host='localhost', port=8000): Max retries exceeded with url: /health (Caused by NewConnectionError('<urllib3.connection.HTTPConnection object at 0x78b80b49e090>: Failed to establish a new connection: [Errno 111] Connection refused'))"
    },
    {
      "timestamp": "2025-07-13T23:03:34.560235",
      "category": "API_ENDPOINTS",
      "test": "Documentation endpoint error",
      "status": "FAIL",
      "details": "",
      "error": "HTTPConnectionPool(host='localhost', port=8000): Max retries exceeded with url: /docs (Caused by NewConnectionError('<urllib3.connection.HTTPConnection object at 0x78b80b49d820>: Failed to establish a new connection: [Errno 111] Connection refused'))"
    },
    {
      "timestamp": "2025-07-13T23:03:34.561198",
      "category": "API_ENDPOINTS",
      "test": "Status endpoint error",
      "status": "FAIL",
      "details": "",
      "error": "HTTPConnectionPool(host='localhost', port=8000): Max retries exceeded with url: /status (Caused by NewConnectionError('<urllib3.connection.HTTPConnection object at 0x78b80b49e450>: Failed to establish a new connection: [Errno 111] Connection refused'))"
    },
    {
      "timestamp": "2025-07-13T23:03:34.561365",
      "category": "CRYPTO",
      "test": "SHA256 hashing",
      "status": "PASS",
      "details": "Hash length: 64",
      "error": null
    },
    {
      "timestamp": "2025-07-13T23:03:34.561432",
      "category": "CRYPTO",
      "test": "Random string generation",
      "status": "PASS",
      "details": "Length: 32",
      "error": null
    },
    {
      "timestamp": "2025-07-13T23:03:34.561494",
      "category": "DATA_VALIDATION",
      "test": "Valid email: test@example.com",
      "status": "PASS",
      "details": "",
      "error": null
    },
    {
      "timestamp": "2025-07-13T23:03:34.561548",
      "category": "DATA_VALIDATION",
      "test": "Valid email: user.name@domain.co.uk",
      "status": "PASS",
      "details": "",
      "error": null
    },
    {
      "timestamp": "2025-07-13T23:03:34.561598",
      "category": "DATA_VALIDATION",
      "test": "Valid email: admin@medivote.org",
      "status": "PASS",
      "details": "",
      "error": null
    },
    {
      "timestamp": "2025-07-13T23:03:34.561665",
      "category": "DATA_VALIDATION",
      "test": "Invalid email rejected: invalid-email",
      "status": "PASS",
      "details": "",
      "error": null
    },
    {
      "timestamp": "2025-07-13T23:03:34.561716",
      "category": "DATA_VALIDATION",
      "test": "Invalid email rejected: @domain.com",
      "status": "FAIL",
      "details": "Should have been rejected",
      "error": null
    },
    {
      "timestamp": "2025-07-13T23:03:34.561809",
      "category": "DATA_VALIDATION",
      "test": "Invalid email rejected: user@",
      "status": "PASS",
      "details": "",
      "error": null
    },
    {
      "timestamp": "2025-07-13T23:03:34.561837",
      "category": "DATA_VALIDATION",
      "test": "Invalid email rejected: user@domain",
      "status": "PASS",
      "details": "",
      "error": null
    },
    {
      "timestamp": "2025-07-13T23:03:34.562010",
      "category": "SECURITY",
      "test": "Strong password accepted: Sec...",
      "status": "PASS",
      "details": "",
      "error": null
    },
    {
      "timestamp": "2025-07-13T23:03:34.562077",
      "category": "SECURITY",
      "test": "Strong password accepted: MyS...",
      "status": "PASS",
      "details": "",
      "error": null
    },
    {
      "timestamp": "2025-07-13T23:03:34.562119",
      "category": "SECURITY",
      "test": "Strong password accepted: C0m...",
      "status": "PASS",
      "details": "",
      "error": null
    },
    {
      "timestamp": "2025-07-13T23:03:34.563798",
      "category": "PERFORMANCE",
      "test": "Response time",
      "status": "FAIL",
      "details": "",
      "error": "HTTPConnectionPool(host='localhost', port=8000): Max retries exceeded with url: /health (Caused by NewConnectionError('<urllib3.connection.HTTPConnection object at 0x78b80b49ea20>: Failed to establish a new connection: [Errno 111] Connection refused'))"
    },
    {
      "timestamp": "2025-07-13T23:03:34.581612",
      "category": "PERFORMANCE",
      "test": "Concurrent requests (10)",
      "status": "FAIL",
      "details": "Only 0/10 successful",
      "error": null
    },
    {
      "timestamp": "2025-07-13T23:03:34.586621",
      "category": "INSTALLER",
      "test": "build_installer.py has content",
      "status": "PASS",
      "details": "Size: 34219 chars",
      "error": null
    },
    {
      "timestamp": "2025-07-13T23:03:34.587247",
      "category": "INSTALLER",
      "test": "build_installer.py has installer logic",
      "status": "PASS",
      "details": "",
      "error": null
    },
    {
      "timestamp": "2025-07-13T23:03:34.591640",
      "category": "INSTALLER",
      "test": "setup.py has content",
      "status": "PASS",
      "details": "Size: 15086 chars",
      "error": null
    },
    {
      "timestamp": "2025-07-13T23:03:34.591858",
      "category": "INSTALLER",
      "test": "setup.py has installer logic",
      "status": "PASS",
      "details": "",
      "error": null
    },
    {
      "timestamp": "2025-07-13T23:03:34.595607",
      "category": "INSTALLER",
      "test": "requirements_build.txt has content",
      "status": "PASS",
      "details": "Size: 1014 chars",
      "error": null
    },
    {
      "timestamp": "2025-07-13T23:03:34.595713",
      "category": "INSTALLER",
      "test": "requirements_build.txt has installer logic",
      "status": "PASS",
      "details": "",
      "error": null
    },
    {
      "timestamp": "2025-07-13T23:03:34.600296",
      "category": "DOCUMENTATION",
      "test": "README.md comprehensive",
      "status": "PASS",
      "details": "995 words",
      "error": null
    },
    {
      "timestamp": "2025-07-13T23:03:34.600395",
      "category": "DOCUMENTATION",
      "test": "README has installation",
      "status": "PASS",
      "details": "",
      "error": null
    },
    {
      "timestamp": "2025-07-13T23:03:34.600471",
      "category": "DOCUMENTATION",
      "test": "README missing usage",
      "status": "WARN",
      "details": "",
      "error": null
    },
    {
      "timestamp": "2025-07-13T23:03:34.600537",
      "category": "DOCUMENTATION",
      "test": "README has features",
      "status": "PASS",
      "details": "",
      "error": null
    },
    {
      "timestamp": "2025-07-13T23:03:34.600603",
      "category": "DOCUMENTATION",
      "test": "README has requirements",
      "status": "PASS",
      "details": "",
      "error": null
    },
    {
      "timestamp": "2025-07-13T23:03:34.605745",
      "category": "DOCUMENTATION",
      "test": "CONTRIBUTING.md comprehensive",
      "status": "PASS",
      "details": "1275 words",
      "error": null
    },
    {
      "timestamp": "2025-07-13T23:03:34.609525",
      "category": "DOCUMENTATION",
      "test": "LICENSE comprehensive",
      "status": "PASS",
      "details": "169 words",
      "error": null
    },
    {
      "timestamp": "2025-07-13T23:03:34.610857",
      "category": "ERROR_HANDLING",
      "test": "Invalid endpoint error",
      "status": "FAIL",
      "details": "",
      "error": "HTTPConnectionPool(host='localhost', port=8000): Max retries exceeded with url: /invalid-endpoint (Caused by NewConnectionError('<urllib3.connection.HTTPConnection object at 0x78b80b4d9af0>: Failed to establish a new connection: [Errno 111] Connection refused'))"
    },
    {
      "timestamp": "2025-07-13T23:03:34.612045",
      "category": "ERROR_HANDLING",
      "test": "POST without data error",
      "status": "FAIL",
      "details": "",
      "error": "HTTPConnectionPool(host='localhost', port=8000): Max retries exceeded with url: /register (Caused by NewConnectionError('<urllib3.connection.HTTPConnection object at 0x78b80b4d9e80>: Failed to establish a new connection: [Errno 111] Connection refused'))"
    },
    {
      "timestamp": "2025-07-13T23:03:34.612907",
      "category": "ERROR_HANDLING",
      "test": "Vote without auth error",
      "status": "FAIL",
      "details": "",
      "error": "HTTPConnectionPool(host='localhost', port=8000): Max retries exceeded with url: /vote (Caused by NewConnectionError('<urllib3.connection.HTTPConnection object at 0x78b80b4da390>: Failed to establish a new connection: [Errno 111] Connection refused'))"
    }
  ],
  "errors": [
    "[PYTHON_ENV] Import sqlalchemy: No module named 'sqlalchemy'",
    "[BACKEND_HEALTH] Server health check: HTTPConnectionPool(host='localhost', port=8000): Max retries exceeded with url: /health (Caused by NewConnectionError('<urllib3.connection.HTTPConnection object at 0x78b80b5ddfd0>: Failed to establish a new connection: [Errno 111] Connection refused'))",
    "[API_ENDPOINTS] Root endpoint error: HTTPConnectionPool(host='localhost', port=8000): Max retries exceeded with url: / (Caused by NewConnectionError('<urllib3.connection.HTTPConnection object at 0x78b80b49d910>: Failed to establish a new connection: [Errno 111] Connection refused'))",
    "[API_ENDPOINTS] Health endpoint error: HTTPConnectionPool(host='localhost', port=8000): Max retries exceeded with url: /health (Caused by NewConnectionError('<urllib3.connection.HTTPConnection object at 0x78b80b49e090>: Failed to establish a new connection: [Errno 111] Connection refused'))",
    "[API_ENDPOINTS] Documentation endpoint error: HTTPConnectionPool(host='localhost', port=8000): Max retries exceeded with url: /docs (Caused by NewConnectionError('<urllib3.connection.HTTPConnection object at 0x78b80b49d820>: Failed to establish a new connection: [Errno 111] Connection refused'))",
    "[API_ENDPOINTS] Status endpoint error: HTTPConnectionPool(host='localhost', port=8000): Max retries exceeded with url: /status (Caused by NewConnectionError('<urllib3.connection.HTTPConnection object at 0x78b80b49e450>: Failed to establish a new connection: [Errno 111] Connection refused'))",
    "[PERFORMANCE] Response time: HTTPConnectionPool(host='localhost', port=8000): Max retries exceeded with url: /health (Caused by NewConnectionError('<urllib3.connection.HTTPConnection object at 0x78b80b49ea20>: Failed to establish a new connection: [Errno 111] Connection refused'))",
    "[ERROR_HANDLING] Invalid endpoint error: HTTPConnectionPool(host='localhost', port=8000): Max retries exceeded with url: /invalid-endpoint (Caused by NewConnectionError('<urllib3.connection.HTTPConnection object at 0x78b80b4d9af0>: Failed to establish a new connection: [Errno 111] Connection refused'))",
    "[ERROR_HANDLING] POST without data error: HTTPConnectionPool(host='localhost', port=8000): Max retries exceeded with url: /register (Caused by NewConnectionError('<urllib3.connection.HTTPConnection object at 0x78b80b4d9e80>: Failed to establish a new connection: [Errno 111] Connection refused'))",
    "[ERROR_HANDLING] Vote without auth error: HTTPConnectionPool(host='localhost', port=8000): Max retries exceeded with url: /vote (Caused by NewConnectionError('<urllib3.connection.HTTPConnection object at 0x78b80b4da390>: Failed to establish a new connection: [Errno 111] Connection refused'))"
  ]
}